<?xml version="1.0" ?>
<!-- =================================================================================== -->
<!-- |    This document was autogenerated by xacro from bb.xacro                       | -->
<!-- |    EDITING THIS FILE BY HAND IS NOT RECOMMENDED                                 | -->
<!-- =================================================================================== -->
<robot name="bb8">
  <material name="blue">
    <color rgba="0 0 .8 1"/>
  </material>
  <material name="black">
    <color rgba="0 0 0 1"/>
  </material>
  <material name="white">
    <color rgba="1 1 1 1"/>
  </material>
  <material name="orange">
    <color rgba="1 .5 0 1"/>
  </material>
  <material name="grey">
    <color rgba=".5 .5 .5 1"/>
  </material>
  <material name="red">
    <color rgba="1 0 0 1"/>
  </material>
  <!-- links without visual -->
  <link name="bb8/base_link"/>
  <link name="bb8/scan"/>
  <link name="bb8/roll"/>
  <link name="bb8/neck"/>
  <link name="bb8/torso"/>
  <joint name="roll" type="revolute">
    <mimic joint="neck" multiplier="0.5"/>
    <axis xyz="-1 0 0"/>
    <limit effort="10" lower="-0.5235987755982988" upper="0.5235987755982988" velocity="2"/>
    <child link="bb8/roll"/>
    <parent link="bb8/base_link"/>
  </joint>
  <joint name="scan" type="fixed">
    <parent link="bb8/base_link"/>
    <child link="bb8/scan"/>
    <origin xyz="0 0 0.27"/>
  </joint>
  <joint name="wheel" type="continuous">
    <parent link="bb8/roll"/>
    <child link="bb8/wheel"/>
    <axis xyz="0 1 0"/>
    <origin xyz="0 0 0.27"/>
  </joint>
  <joint name="torso" type="revolute">
    <axis xyz="0 1 0"/>
    <limit effort="10" lower="-0.7853981633974483" upper="0.7853981633974483" velocity="2"/>
    <child link="bb8/torso"/>
    <parent link="bb8/roll"/>
    <origin xyz="0 0 0.27"/>
  </joint>
  <joint name="neck" type="revolute">
    <parent link="bb8/torso"/>
    <child link="bb8/neck"/>
    <origin xyz="0 0 0.27"/>
    <axis xyz="-1 0 0"/>
    <limit effort="10" lower="-0.5235987755982988" upper="0.5235987755982988" velocity="2"/>
  </joint>
  <joint name="head" type="fixed">
    <parent link="bb8/neck"/>
    <child link="bb8/head"/>
    <origin xyz="0 0 0.027000000000000003"/>
  </joint>
  <link name="bb8/head">
    <visual>
      <geometry>
        <sphere radius="0.14040000000000002"/>
      </geometry>
      <material name="white"/>
    </visual>
  </link>
  <link name="bb8/eye">
    <visual>
      <geometry>
        <cylinder length="0.0945" radius="0.0324"/>
      </geometry>
      <material name="black"/>
    </visual>
  </link>
  <joint name="eye" type="fixed">
    <parent link="bb8/head"/>
    <child link="bb8/eye"/>
    <origin rpy="0 1.5707963267948966 0" xyz="0.0864 0 0.054000000000000006"/>
  </joint>
  <link name="bb8/crown">
    <visual>
      <geometry>
        <cylinder length="0.0945" radius="0.0945"/>
      </geometry>
      <material name="grey"/>
    </visual>
  </link>
  <joint name="crown" type="fixed">
    <parent link="bb8/head"/>
    <child link="bb8/crown"/>
    <origin xyz="0 0 0.0675"/>
  </joint>
  <!-- wheel links -->
  <link name="bb8/wheel">
    <visual>
      <geometry>
        <sphere radius="0.27"/>
      </geometry>
      <material name="white"/>
    </visual>
  </link>
  <link name="bb8/cx">
    <visual>
      <geometry>
        <cylinder length="0.47790000000000005" radius="0.135"/>
      </geometry>
      <material name="orange"/>
    </visual>
  </link>
  <joint name="cx" type="fixed">
    <parent link="bb8/wheel"/>
    <child link="bb8/cx"/>
    <origin rpy="1.5707963267948966 0 0"/>
  </joint>
  <link name="bb8/cz">
    <visual>
      <geometry>
        <cylinder length="0.47790000000000005" radius="0.135"/>
      </geometry>
      <material name="orange"/>
    </visual>
  </link>
  <joint name="cz" type="fixed">
    <parent link="bb8/wheel"/>
    <child link="bb8/cz"/>
    <origin rpy="0 0 0"/>
  </joint>
  <link name="bb8/cy">
    <visual>
      <geometry>
        <cylinder length="0.47790000000000005" radius="0.135"/>
      </geometry>
      <material name="orange"/>
    </visual>
  </link>
  <joint name="cy" type="fixed">
    <parent link="bb8/wheel"/>
    <child link="bb8/cy"/>
    <origin rpy="0 1.5707963267948966 0"/>
  </joint>
</robot>
